Workbook
Name Roman: #REF!
Name Roman: #REF!
Name Roman: #REF!
Name Roman: #REF!
Name Roman: #REF!
Name Roman: #REF!

Sheet Reported LDFs
A1: Development | B1: Indemnity LDF | C1: Medical LDF
A2: 12–24 | B2: =Base_Indem_Tri!B48 -> 1.4031315 | C2: =Base_Med_Tri!B48 -> 1.2860574
A3: 24–36 | B3: =Base_Indem_Tri!C48 -> 1.1231878 | C3: =Base_Med_Tri!C48 -> 1.0215737
A4: 36–48 | B4: =Base_Indem_Tri!D48 -> 1.0330305 | C4: =Base_Med_Tri!D48 -> 0.98774838
A5: 48–60 | B5: =Base_Indem_Tri!E48 -> 1.0012 | C5: =Base_Med_Tri!E48 -> 0.985
A6: 60–72 | B6: =Base_Indem_Tri!F48 -> 0.9952 | C6: =Base_Med_Tri!F48 -> 0.99084997
A7: 72–84 | B7: =Base_Indem_Tri!G48 -> 0.9952 | C7: =Base_Med_Tri!G48 -> 0.986
A8: 84–96 | B8: =Base_Indem_Tri!H48 -> 0.9948 | C8: =Base_Med_Tri!H48 -> 1.0006
A9: 96–108 | B9: =Base_Indem_Tri!I48 -> 1.0122285 | C9: =Base_Med_Tri!I48 -> 1.0352691
A10: 108–120 | B10: =Base_Indem_Tri!J48 -> 1.0073765 | C10: =Base_Med_Tri!J48 -> 1.0248909
A11: 120–132 | B11: =Base_Indem_Tri!K48 -> 1.0001228 | C11: =Base_Med_Tri!K48 -> 1.0051287
A12: 132–144 | B12: =Base_Indem_Tri!L48 -> 1.0054589 | C12: =Base_Med_Tri!L48 -> 1.005724
A13: 144–156 | B13: =Base_Indem_Tri!M48 -> 0.99009901 | C13: =Base_Med_Tri!M48 -> 0.99009901

Sheet Paid LDFs
A1: Development | B1: Indemnity LDF | C1: Medical LDF
A2: 46015 | B2: =Base_Indem_Tri!Q48 -> 2.8823075 | C2: =Base_Med_Tri!Q48 -> 1.964579
A3: 24-36 | B3: =Base_Indem_Tri!R48 -> 1.5384639 | C3: =Base_Med_Tri!R48 -> 1.1195773
A4: 36-48 | B4: =Base_Indem_Tri!S48 -> 1.2300381 | C4: =Base_Med_Tri!S48 -> 1.0520769
A5: 48-60 | B5: =Base_Indem_Tri!T48 -> 1.1204 | C5: =Base_Med_Tri!T48 -> 1.0184
A6: 60-72 | B6: =Base_Indem_Tri!U48 -> 1.0608 | C6: =Base_Med_Tri!U48 -> 1.0096
A7: 72-84 | B7: =Base_Indem_Tri!V48 -> 1.0318 | C7: =Base_Med_Tri!V48 -> 1.0044
A8: 84-96 | B8: =Base_Indem_Tri!W48 -> 1.0188 | C8: =Base_Med_Tri!W48 -> 1.0046
A9: 96-108 | B9: =Base_Indem_Tri!X48 -> 1.0203234 | C9: =Base_Med_Tri!X48 -> 1.0243003
A10: 108-120 | B10: =Base_Indem_Tri!Y48 -> 1.0186187 | C10: =Base_Med_Tri!Y48 -> 1.022697
A11: 120-132 | B11: =Base_Indem_Tri!Z48 -> 1.0156392 | C11: =Base_Med_Tri!Z48 -> 1.0204455
A12: 132-144 | B12: =Base_Indem_Tri!AA48 -> 1.0204223 | C12: =Base_Med_Tri!AA48 -> 1.0218775
A13: 144-156 | B13: =Base_Indem_Tri!AB48 -> 1.0069987 | C13: =Base_Med_Tri!AB48 -> 1.0249491

Sheet Catastrophe Adjustment (Outlier
F1: Development Period (Months) | G1: LDFs (All Years) | H1: LDFs (Excl. 2012) | I1: Difference (%)
F2: 46015 | G2: 1.4031 | H2: 1.3848 | I2: =G2-H2 -> 0.0183
F3: 24-36 | G3: 1.1232 | H3: 1.1178 | I3: =G3-H3 -> 0.0054
F4: 36-48 | G4: 1.033 | H4: 1.0328 | I4: =G4-H4 -> 0.0002
F5: 48-60 | G5: 1.0012 | H5: 1.0012 | I5: =G5-H5 -> 0
F6: 60-72 | G6: 0.9952 | H6: 0.9952 | I6: =G6-H6 -> 0
F7: 72-84 | G7: 0.9952 | H7: 0.9952 | I7: =G7-H7 -> 0
F8: 84-96 | G8: 0.9948 | H8: 0.9948 | I8: =G8-H8 -> 0
F9: 96-108 | G9: 1.0122 | H9: 1.0122 | I9: =G9-H9 -> 0
F10: 108-120 | G10: 1.0074 | H10: 1.0074 | I10: =G10-H10 -> 0
F11: 120-132 | G11: 1.0001 | H11: 1.0001 | I11: =G11-H11 -> 0
F12: 132-144 | G12: 1.0055 | H12: 1.0055 | I12: =G12-H12 -> 0
F13: 144-156 | G13: 0.9901 | H13: 0.9901 | I13: =G13-H13 -> 0

Sheet Intro
B2: Workers Compensation Reserving Case Study
B4: A | C4: Introduction to Reserving (Loss Development)
C6: Step | D6: Tab Names | E6: Instructions
C7: 1 | D7: Summary | E7: 1.1 Read Chapter 5-7 of Friedland's textbook. Exhibit I of Chapter 7 can be referred to as an example;
E8: Friedland's textbook
E9: 1.2 The exhibits at the end of Chapter 7 of Friedland's textbook can be referred to as examples;
C10: 2 | D10: Base_Indem_Tri | E10: 2.1 Start with the given paid loss triangle and the incurred loss triangle, perform any data analysis required (such as identifying outliers);
E11: 2.2 Select incremental loss development factors for paid and incurred loss triangles in the blue cells;
E12: 2.3 Compare the selections for paid and incurred loss development factors in the '% of Ult' tab, and make adjustments as necessary;
C13: 3 | D13: Base_Med_Tri | E13: 3.1 Start with the given paid loss triangle and the incurred loss triangle, perform any data analysis required (such as identifying outliers);
E14: 3.2 Select incremental loss development factors for paid and incurred loss triangles in the blue cells;
E15: 3.3 Compare the selections for paid and incurred loss development factors in the '% of Ult' tab, and make adjustments as necessary;
C16: 4 | D16: Summary | E16: 4.1 Compare the results of the paid loss development method against the incurred loss development method;
E17: 4.2 Reflect on the reasons behind the differences, if any, and make adjustments as necessary;
E18: 4.3 Reflect and answer the questions in the case study;
B20: B | C20: In-Depth Considerations (Frequency/Severity, Catastrophe, and Tail Factor)
C22: Step | D22: Tab Names | E22: Instructions
C23: 1 | D23: Summary Freq&Sev | E23: 1.1 Read Chapter 11 of Friedland's textbook, feel free to skip over Frequency Severity Approach #2;
E24: Friedland's textbook
E25: 1.2 The exhibits at the end of Chapter 7 of Friedland's textbook can be referred to as examples;
C26: 2 | D26: Rep_Tri | E26: 2.1 Select incremental claim count development factors;
C27: 3 | E27: 3.1 Refer to Part A Step 2;
D28: Base_Indem_Sev | E28: 3.2 Consider the effect of the catastrophic event given in the 'Catastrophe" tab as well as tail factors in the yellow cells (development beyond the latest data in the triangle)
C29: 4 | D29: Base_Med_Sev | E29: 3.1 Refer to Part A Step 3;
E30: 3.2 Consider the effect of the catastrophic event given in the 'Catastrophe" tab as well as tail factors in the yellow cells (development beyond the latest data in the triangle)
C31: 5 | D31: Summary Freq&Sev | E31: 5.1 Compare the results of the frequency/severity method against the loss development method in part A;
E32: 5.2 Reflect and answer the questions in the case study;

Sheet Summary
B2: TOU Insurance Company - Workers Compensation
B3: Development of Unpaid Claim Estimate | Q3: Paid Loss Development | V3: Paid Loss Development
B4: Indemnity + Medical | Q4: Indemnity | V4: Medical
F6: Case | G6: Project Ultimate Claims | I6: Projected | K6: Unpaid Claim Estimate | Q6: Accident | R6: Paid | S6: Selected | T6: Ultimate | V6: Accident | W6: Paid | X6: Selected | Y6: Ultimate
B7: Accident | C7: Earned | D7: ="Claims at 12/31/" & B23 -> Claims at 12/31/2015 | F7: Outstanding | G7: Using Loss Development | I7: Ultimate Loss Ratios | K7: IBNR | M7: Total Unpaid | Q7: Year | R7: Losses | S7: LDFs | T7: Losses $000s | V7: Year | W7: Losses | X7: LDFs | Y7: Losses $000s
B8: Year | C8: Premiums | D8: Paid | E8: Reported | F8: ="At 12/31/" & B23 -> At 12/31/2015 | G8: Paid | H8: Reported | I8: Paid | J8: Reported | K8: Paid | L8: Reported | M8: Paid | N8: Reported | Q8: =Base_Indem_Tri!P8 -> 2003 | R8: =Base_Indem_Tri!AC8 -> 71881.089 | S8: =Base_Indem_Tri!$AC$57 -> 1 | T8: =R8*S8 -> 71881.089 | V8: =Q8 -> 2003 | W8: =Base_Med_Tri!AC8 -> 74815.011 | X8: =Base_Med_Tri!$AC$57 -> 1 | Y8: =W8*X8 -> 74815.011
B9: -1 | C9: =B9-1 -> -2 | D9: =C9-1 -> -3 | E9: =D9-1 -> -4 | F9: =E9-1 -> -5 | G9: =F9-1 -> -6 | H9: =G9-1 -> -7 | I9: =H9-1 -> -8 | J9: =I9-1 -> -9 | ... N9: =M9-1 -> -13 | Q9: =Base_Indem_Tri!P9 -> 2004 | R9: =Base_Indem_Tri!AB9 -> 72728.844 | S9: =Base_Indem_Tri!AB57 -> 1 | T9: =R9*S9 -> 72728.844 | V9: =Q9 -> 2004 | W9: =Base_Med_Tri!AB9 -> 74371.647 | X9: =Base_Med_Tri!AB57 -> 1 | Y9: =W9*X9 -> 74371.647
Q10: =Base_Indem_Tri!P10 -> 2005 | R10: =Base_Indem_Tri!AA10 -> 67848.685 | S10: =Base_Indem_Tri!AA57 -> 1 | T10: =R10*S10 -> 67848.685 | V10: =Q10 -> 2005 | W10: =Base_Med_Tri!AA10 -> 75063.219 | X10: =Base_Med_Tri!AA57 -> 1 | Y10: =W10*X10 -> 75063.219
B11: =Q8 -> 2003 | C11: 206600 | D11: =R8+W8 -> 146696.1 | E11: =R28+W28 -> 146696.1 | F11: =E11-D11 -> 0 | G11: =T8+Y8 -> 146696.1 | H11: =T28+Y28 -> 146696.1 | I11: =G11/$C11 -> 0.71004889 | J11: =H11/$C11 -> 0.71004889 | K11: =G11-E11 -> 0 | L11: =H11-E11 -> 0 | M11: =K11+F11 -> 0 | N11: =L11+F11 -> 0 | Q11: =Base_Indem_Tri!P11 -> 2006 | R11: =Base_Indem_Tri!Z11 -> 64300.664 | S11: =Base_Indem_Tri!Z57 -> 1 | T11: =R11*S11 -> 64300.664 | V11: =Q11 -> 2006 | W11: =Base_Med_Tri!Z11 -> 73809.197 | X11: =Base_Med_Tri!Z57 -> 1 | Y11: =W11*X11 -> 73809.197
B12: =Q9 -> 2004 | C12: 210500 | D12: =R9+W9 -> 147100.49 | E12: =R29+W29 -> 150959.65 | F12: =E12-D12 -> 3859.1597 | G12: =T9+Y9 -> 147100.49 | H12: =T29+Y29 -> 150959.65 | I12: =G12/$C12 -> 0.69881468 | J12: =H12/$C12 -> 0.71714798 | K12: =G12-E12 -> -3859.1597 | L12: =H12-E12 -> 0 | M12: =K12+F12 -> 0 | N12: =L12+F12 -> 3859.1597 | Q12: =Base_Indem_Tri!P12 -> 2007 | R12: =Base_Indem_Tri!Y12 -> 64477.685 | S12: =Base_Indem_Tri!Y57 -> 1 | T12: =R12*S12 -> 64477.685 | V12: =Q12 -> 2007 | W12: =Base_Med_Tri!Y12 -> 73620.281 | X12: =Base_Med_Tri!Y57 -> 1 | Y12: =W12*X12 -> 73620.281
B13: =Q10 -> 2005 | C13: 215000 | D13: =R10+W10 -> 142911.9 | E13: =R30+W30 -> 148987.14 | F13: =E13-D13 -> 6075.2383 | G13: =T10+Y10 -> 142911.9 | H13: =T30+Y30 -> 148987.14 | I13: =G13/$C13 -> 0.66470653 | J13: =H13/$C13 -> 0.69296345 | K13: =G13-E13 -> -6075.2383 | L13: =H13-E13 -> 0 | M13: =K13+F13 -> 0 | N13: =L13+F13 -> 6075.2383 | Q13: =Base_Indem_Tri!P13 -> 2008 | R13: =Base_Indem_Tri!X13 -> 65727.56 | S13: =Base_Indem_Tri!X57 -> 1 | T13: =R13*S13 -> 65727.56 | V13: =Q13 -> 2008 | W13: =Base_Med_Tri!X13 -> 71917.73 | X13: =Base_Med_Tri!X57 -> 1 | Y13: =W13*X13 -> 71917.73
B14: =Q11 -> 2006 | C14: 225300 | D14: =R11+W11 -> 138109.86 | E14: =R31+W31 -> 146037.76 | F14: =E14-D14 -> 7927.9005 | G14: =T11+Y11 -> 138109.86 | H14: =T31+Y31 -> 146037.76 | I14: =G14/$C14 -> 0.61300426 | J14: =H14/$C14 -> 0.64819246 | K14: =G14-E14 -> -7927.9005 | L14: =H14-E14 -> 0 | M14: =K14+F14 -> 0 | N14: =L14+F14 -> 7927.9005 | Q14: =Base_Indem_Tri!P14 -> 2009 | R14: =Base_Indem_Tri!W14 -> 68110.91 | S14: =Base_Indem_Tri!W57 -> 1 | T14: =R14*S14 -> 68110.91 | V14: =Q14 -> 2009 | W14: =Base_Med_Tri!W14 -> 75516.222 | X14: =Base_Med_Tri!W57 -> 1 | Y14: =W14*X14 -> 75516.222
B15: =Q12 -> 2007 | C15: 253500 | D15: =R12+W12 -> 138097.97 | E15: =R32+W32 -> 146506.69 | F15: =E15-D15 -> 8408.7198 | G15: =T12+Y12 -> 138097.97 | H15: =T32+Y32 -> 146506.69 | I15: =G15/$C15 -> 0.54476515 | J15: =H15/$C15 -> 0.57793564 | K15: =G15-E15 -> -8408.7198 | L15: =H15-E15 -> 0 | M15: =K15+F15 -> 0 | N15: =L15+F15 -> 8408.7198 | Q15: =Base_Indem_Tri!P15 -> 2010 | R15: =Base_Indem_Tri!V15 -> 62485.197 | S15: =Base_Indem_Tri!V57 -> 1 | T15: =R15*S15 -> 62485.197 | V15: =Q15 -> 2010 | W15: =Base_Med_Tri!V15 -> 73984.053 | X15: =Base_Med_Tri!V57 -> 1 | Y15: =W15*X15 -> 73984.053
B16: =Q13 -> 2008 | C16: 253500 | D16: =R13+W13 -> 137645.29 | E16: =R33+W33 -> 146315.96 | F16: =E16-D16 -> 8670.671 | G16: =T13+Y13 -> 137645.29 | H16: =T33+Y33 -> 146315.96 | I16: =G16/$C16 -> 0.54297945 | J16: =H16/$C16 -> 0.57718328 | K16: =G16-E16 -> -8670.671 | L16: =H16-E16 -> 0 | M16: =K16+F16 -> 0 | N16: =L16+F16 -> 8670.671 | Q16: =Base_Indem_Tri!P16 -> 2011 | R16: =Base_Indem_Tri!U16 -> 61009.463 | S16: =Base_Indem_Tri!U57 -> 1 | T16: =R16*S16 -> 61009.463 | V16: =Q16 -> 2011 | W16: =Base_Med_Tri!U16 -> 75968.398 | X16: =Base_Med_Tri!U57 -> 1 | Y16: =W16*X16 -> 75968.398
B17: =Q14 -> 2009 | C17: 267200 | D17: =R14+W14 -> 143627.13 | E17: =R34+W34 -> 154924.7 | F17: =E17-D17 -> 11297.563 | G17: =T14+Y14 -> 143627.13 | H17: =T34+Y34 -> 154924.7 | I17: =G17/$C17 -> 0.53752669 | J17: =H17/$C17 -> 0.57980799 | K17: =G17-E17 -> -11297.563 | L17: =H17-E17 -> 0 | M17: =K17+F17 -> 0 | N17: =L17+F17 -> 11297.563 | Q17: =Base_Indem_Tri!P17 -> 2012 | R17: =Base_Indem_Tri!T17 -> 62041.374 | S17: =Base_Indem_Tri!T57 -> 1 | T17: =R17*S17 -> 62041.374 | V17: =Q17 -> 2012 | W17: =Base_Med_Tri!T17 -> 88998.627 | X17: =Base_Med_Tri!T57 -> 1 | Y17: =W17*X17 -> 88998.627
B18: =Q15 -> 2010 | C18: 227700 | D18: =R15+W15 -> 136469.25 | E18: =R35+W35 -> 150887.79 | F18: =E18-D18 -> 14418.537 | G18: =T15+Y15 -> 136469.25 | H18: =T35+Y35 -> 150887.79 | I18: =G18/$C18 -> 0.59933794 | J18: =H18/$C18 -> 0.66266046 | K18: =G18-E18 -> -14418.537 | L18: =H18-E18 -> 0 | M18: =K18+F18 -> 0 | N18: =L18+F18 -> 14418.537 | Q18: =Base_Indem_Tri!P18 -> 2013 | R18: =Base_Indem_Tri!S18 -> 41159.998 | S18: =Base_Indem_Tri!S57 -> 1 | T18: =R18*S18 -> 41159.998 | V18: =Q18 -> 2013 | W18: =Base_Med_Tri!S18 -> 69374.753 | X18: =Base_Med_Tri!S57 -> 1 | Y18: =W18*X18 -> 69374.753
B19: =Q16 -> 2011 | C19: 225800 | D19: =R16+W16 -> 136977.86 | E19: =R36+W36 -> 157390.37 | F19: =E19-D19 -> 20412.504 | G19: =T16+Y16 -> 136977.86 | H19: =T36+Y36 -> 157390.37 | I19: =G19/$C19 -> 0.60663358 | J19: =H19/$C19 -> 0.69703439 | K19: =G19-E19 -> -20412.504 | L19: =H19-E19 -> 0 | M19: =K19+F19 -> 0 | N19: =L19+F19 -> 20412.504 | Q19: =Base_Indem_Tri!P19 -> 2014 | R19: =Base_Indem_Tri!R19 -> 26495.238 | S19: =Base_Indem_Tri!R57 -> 1 | T19: =R19*S19 -> 26495.238 | V19: =Q19 -> 2014 | W19: =Base_Med_Tri!R19 -> 64406.01 | X19: =Base_Med_Tri!R57 -> 1 | Y19: =W19*X19 -> 64406.01
B20: =Q17 -> 2012 | C20: 231900 | D20: =R17+W17 -> 151040 | E20: =R37+W37 -> 180451.43 | F20: =E20-D20 -> 29411.431 | G20: =T17+Y17 -> 151040 | H20: =T37+Y37 -> 180451.43 | I20: =G20/$C20 -> 0.65131523 | J20: =H20/$C20 -> 0.7781433 | K20: =G20-E20 -> -29411.431 | L20: =H20-E20 -> 0 | M20: =K20+F20 -> 0 | N20: =L20+F20 -> 29411.431 | Q20: =Base_Indem_Tri!P20 -> 2015 | R20: =Base_Indem_Tri!Q20 -> 9643.9885 | S20: =Base_Indem_Tri!Q57 -> 1 | T20: =R20*S20 -> 9643.9885 | V20: =Q20 -> 2015 | W20: =Base_Med_Tri!Q20 -> 32876.614 | X20: =Base_Med_Tri!Q57 -> 1 | Y20: =W20*X20 -> 32876.614
B21: =Q18 -> 2013 | C21: 230100 | D21: =R18+W18 -> 110534.75 | E21: =R38+W38 -> 148527.89 | F21: =E21-D21 -> 37993.14 | G21: =T18+Y18 -> 110534.75 | H21: =T38+Y38 -> 148527.89 | I21: =G21/$C21 -> 0.48037701 | J21: =H21/$C21 -> 0.64549279 | K21: =G21-E21 -> -37993.14 | L21: =H21-E21 -> 0 | M21: =K21+F21 -> 0 | N21: =L21+F21 -> 37993.14
B22: =Q19 -> 2014 | C22: 253100 | D22: =R19+W19 -> 90901.248 | E22: =R39+W39 -> 143202.85 | F22: =E22-D22 -> 52301.6 | G22: =T19+Y19 -> 90901.248 | H22: =T39+Y39 -> 143202.85 | I22: =G22/$C22 -> 0.35915151 | J22: =H22/$C22 -> 0.56579553 | K22: =G22-E22 -> -52301.6 | L22: =H22-E22 -> 0 | M22: =K22+F22 -> 0 | N22: =L22+F22 -> 52301.6
B23: =Q20 -> 2015 | C23: 269000 | D23: =R20+W20 -> 42520.602 | E23: =R40+W40 -> 109127.59 | F23: =E23-D23 -> 66606.988 | G23: =T20+Y20 -> 42520.602 | H23: =T40+Y40 -> 109127.59 | I23: =G23/$C23 -> 0.15806915 | J23: =H23/$C23 -> 0.40567877 | K23: =G23-E23 -> -66606.988 | L23: =H23-E23 -> 0 | M23: =K23+F23 -> 0 | N23: =L23+F23 -> 66606.988 | Q23: Reported Loss Development | V23: Reported Loss Development
Q24: Indemnity | V24: Medical
B25: Total | C25: =SUM(C11:C23) -> 3069200 | D25: =SUM(D11:D23) -> 1662632.5 | E25: =SUM(E11:E23) -> 1930015.9 | F25: =SUM(F11:F23) -> 267383.45 | G25: =SUM(G11:G23) -> 1662632.5 | H25: =SUM(H11:H23) -> 1930015.9 | I25: =G25/$C25 -> 0.54171525 | J25: =H25/$C25 -> 0.62883354 | K25: =SUM(K11:K23) -> -267383.45 | L25: =SUM(L11:L23) -> 0 | M25: =SUM(M11:M23) -> 0 | N25: =SUM(N11:N23) -> 267383.45
Q26: Accident | R26: Reported | S26: Selected | T26: Ultimate | V26: Accident | W26: Reported | X26: Selected | Y26: Ultimate
B27: -1 | C27: Provided by Company XYZ | F27: =B33-1 -> -8 | G27: = (6) / (2) | Q27: Year | R27: Losses | S27: LDFs | T27: Losses $000s | V27: Year | W27: Losses | X27: LDFs | Y27: Losses $000s
B28: =B27-1 -> -2 | C28: Provided by Company XYZ | F28: =F27-1 -> -9 | G28: = (7) / (2) | Q28: =Base_Indem_Tri!A8 -> 2003 | R28: =Base_Indem_Tri!N8 -> 71881.089 | S28: =Base_Indem_Tri!$N$57 -> 1 | T28: =R28*S28 -> 71881.089 | V28: =Q28 -> 2003 | W28: =Base_Med_Tri!N8 -> 74815.011 | X28: =Base_Med_Tri!$N$57 -> 1 | Y28: =W28*X28 -> 74815.011
B29: =B28-1 -> -3 | C29: Provided by Company XYZ | F29: =F28-1 -> -10 | G29: = (6) - (4) | Q29: =Base_Indem_Tri!A9 -> 2004 | R29: =Base_Indem_Tri!M9 -> 73970.228 | S29: =Base_Indem_Tri!M57 -> 1 | T29: =R29*S29 -> 73970.228 | V29: =Q29 -> 2004 | W29: =Base_Med_Tri!M9 -> 76989.421 | X29: =Base_Med_Tri!M57 -> 1 | Y29: =W29*X29 -> 76989.421
B30: =B29-1 -> -4 | C30: Provided by Company XYZ | F30: =F29-1 -> -11 | G30: = (7) - (4) | Q30: =Base_Indem_Tri!A10 -> 2005 | R30: =Base_Indem_Tri!L10 -> 70033.739 | S30: =Base_Indem_Tri!L57 -> 1 | T30: =R30*S30 -> 70033.739 | V30: =Q30 -> 2005 | W30: =Base_Med_Tri!L10 -> 78953.403 | X30: =Base_Med_Tri!L57 -> 1 | Y30: =W30*X30 -> 78953.403
B31: =B30-1 -> -5 | C31: = (4) - (3) | F31: =F30-1 -> -12 | G31: = (5) + (10) | Q31: =Base_Indem_Tri!A11 -> 2006 | R31: =Base_Indem_Tri!K11 -> 67339.672 | S31: =Base_Indem_Tri!K57 -> 1 | T31: =R31*S31 -> 67339.672 | V31: =Q31 -> 2006 | W31: =Base_Med_Tri!K11 -> 78698.088 | X31: =Base_Med_Tri!K57 -> 1 | Y31: =W31*X31 -> 78698.088
B32: =B31-1 -> -6 | C32: Selected by Actuary | F32: =F31-1 -> -13 | G32: = (5) + (11) | Q32: =Base_Indem_Tri!A12 -> 2007 | R32: =Base_Indem_Tri!J12 -> 68355.431 | S32: =Base_Indem_Tri!J57 -> 1 | T32: =R32*S32 -> 68355.431 | V32: =Q32 -> 2007 | W32: =Base_Med_Tri!J12 -> 78151.254 | X32: =Base_Med_Tri!J57 -> 1 | Y32: =W32*X32 -> 78151.254
B33: =B32-1 -> -7 | C33: Selected by Actuary | Q33: =Base_Indem_Tri!A13 -> 2008 | R33: =Base_Indem_Tri!I13 -> 70556.413 | S33: =Base_Indem_Tri!I57 -> 1 | T33: =R33*S33 -> 70556.413 | V33: =Q33 -> 2008 | W33: =Base_Med_Tri!I13 -> 75759.548 | X33: =Base_Med_Tri!I57 -> 1 | Y33: =W33*X33 -> 75759.548
Q34: =Base_Indem_Tri!A14 -> 2009 | R34: =Base_Indem_Tri!H14 -> 74956.071 | S34: =Base_Indem_Tri!H57 -> 1 | T34: =R34*S34 -> 74956.071 | V34: =Q34 -> 2009 | W34: =Base_Med_Tri!H14 -> 79968.625 | X34: =Base_Med_Tri!H57 -> 1 | Y34: =W34*X34 -> 79968.625
Q35: =Base_Indem_Tri!A15 -> 2010 | R35: =Base_Indem_Tri!G15 -> 71115.754 | S35: =Base_Indem_Tri!G57 -> 1 | T35: =R35*S35 -> 71115.754 | V35: =Q35 -> 2010 | W35: =Base_Med_Tri!G15 -> 79772.033 | X35: =Base_Med_Tri!G57 -> 1 | Y35: =W35*X35 -> 79772.033
Q36: =Base_Indem_Tri!A16 -> 2011 | R36: =Base_Indem_Tri!F16 -> 73880.677 | S36: =Base_Indem_Tri!F57 -> 1 | T36: =R36*S36 -> 73880.677 | V36: =Q36 -> 2011 | W36: =Base_Med_Tri!F16 -> 83509.688 | X36: =Base_Med_Tri!F57 -> 1 | Y36: =W36*X36 -> 83509.688
Q37: =Base_Indem_Tri!A17 -> 2012 | R37: =Base_Indem_Tri!E17 -> 81042.886 | S37: =Base_Indem_Tri!E57 -> 1 | T37: =R37*S37 -> 81042.886 | V37: =Q37 -> 2012 | W37: =Base_Med_Tri!E17 -> 99408.546 | X37: =Base_Med_Tri!E57 -> 1 | Y37: =W37*X37 -> 99408.546
Q38: =Base_Indem_Tri!A18 -> 2013 | R38: =Base_Indem_Tri!D18 -> 65798.394 | S38: =Base_Indem_Tri!D57 -> 1 | T38: =R38*S38 -> 65798.394 | V38: =Q38 -> 2013 | W38: =Base_Med_Tri!D18 -> 82729.497 | X38: =Base_Med_Tri!D57 -> 1 | Y38: =W38*X38 -> 82729.497
Q39: =Base_Indem_Tri!A19 -> 2014 | R39: =Base_Indem_Tri!C19 -> 58386.843 | S39: =Base_Indem_Tri!C57 -> 1 | T39: =R39*S39 -> 58386.843 | V39: =Q39 -> 2014 | W39: =Base_Med_Tri!C19 -> 84816.006 | X39: =Base_Med_Tri!C57 -> 1 | Y39: =W39*X39 -> 84816.006
Q40: =Base_Indem_Tri!A20 -> 2015 | R40: =Base_Indem_Tri!B20 -> 43013.271 | S40: =Base_Indem_Tri!B57 -> 1 | T40: =R40*S40 -> 43013.271 | V40: =Q40 -> 2015 | W40: =Base_Med_Tri!B20 -> 66114.319 | X40: =Base_Med_Tri!B57 -> 1 | Y40: =W40*X40 -> 66114.319

Sheet Base_Indem_Tri
B2: Direct Accident Year Case Reported Loss Development Factors | Q2: Direct Accident Year Paid Loss Development Factors
B3: INDEMNITY in $Thousands | Q3: INDEMNITY in $Thousands
A5: Accident | P5: Accident
A6: Year | B6: 12 | C6: 24 | D6: 36 | E6: 48 | F6: 60 | G6: 72 | H6: 84 | I6: 96 | J6: 108 | K6: 120 | L6: 132 | M6: 144 | N6: 156 | P6: Year | Q6: 12 | R6: 24 | S6: 36 | T6: 48 | U6: 60 | V6: 72 | W6: 84 | X6: 96 | Y6: 108 | Z6: 120 | AA6: 132 | AB6: 144 | AC6: 156
A8: 2003 | I8: 70540.814 | J8: 71919.876 | K8: 72609.692 | L8: 71234.083 | M8: 72599.9 | N8: 71881.089 | P8: 2003 | X8: 66618.247 | Y8: 68315.439 | Z8: 69881.816 | AA8: 69881.816 | AB8: 71381.512 | AC8: 71881.089
A9: 2004 | H9: 69294.577 | I9: 68809.515 | J9: 72056.656 | K9: 72752.252 | L9: 74585.994 | M9: 73970.229 | P9: 2004 | W9: 64521.02 | X9: 65488.835 | Y9: 67935.673 | Z9: 68906.784 | AA9: 71345.865 | AB9: 72728.844
A10: 2005 | G10: 70202.161 | H10: 69640.544 | I10: 69501.263 | J10: 69046.652 | K10: 70448.809 | L10: 70033.739 | P10: 2005 | V10: 61869.596 | W10: 63725.684 | X10: 65127.649 | Y10: 65354.779 | Z10: 67075.927 | AA10: 67848.685
A11: 2006 | F11: 68891.925 | G11: 68271.898 | H11: 67384.363 | I11: 67586.517 | J11: 68023.044 | K11: 67339.672 | P11: 2006 | U11: 55420.944 | V11: 58746.2 | W11: 60626.079 | X11: 62141.731 | Y11: 63606.318 | Z11: 64300.664
A12: 2007 | E12: 69499.487 | F12: 69568.986 | G12: 69221.141 | H12: 69428.805 | I12: 68734.517 | J12: 68355.431 | P12: 2007 | T12: 50694.623 | U12: 56524.504 | V12: 60255.122 | W12: 62665.327 | X12: 63730.637 | Y12: 64477.685
A13: 2008 | D13: 69206.59 | E13: 71628.82 | F13: 71915.336 | G13: 71411.928 | H13: 71269.104 | I13: 70556.413 | P13: 2008 | S13: 43162.458 | T13: 52312.9 | U13: 59479.767 | V13: 62870.114 | W13: 64756.217 | X13: 65727.56
A14: 2009 | C14: 66890.9 | D14: 73513.099 | E14: 75939.032 | F14: 75635.275 | G14: 75257.099 | H14: 74956.071 | P14: 2009 | R14: 29996.407 | S14: 45234.582 | T14: 55909.943 | U14: 62507.317 | V14: 66320.263 | W14: 68110.91
A15: 2010 | B15: 47025.198 | C15: 62026.236 | D15: 68849.122 | E15: 71258.842 | F15: 70973.806 | G15: 71115.754 | P15: 2010 | Q15: 10418.129 | R15: 27680.969 | S15: 42905.503 | T15: 52773.768 | U15: 58948.299 | V15: 62485.197
A16: 2011 | B16: 46780.55 | C16: 63995.793 | D16: 71227.317 | E16: 73221.682 | F16: 73880.677 | P16: 2011 | Q16: 10469.768 | R16: 28634.815 | S16: 44269.423 | T16: 54717.007 | U16: 61009.463
A17: 2012 | B17: 46351.969 | C17: 68445.974 | D17: 78366.463 | E17: 81042.886 | P17: 2012 | Q17: 9887.831 | R17: 32289.085 | S17: 50187.55 | T17: 62041.374
A18: 2013 | B18: 42576.796 | C18: 57265.791 | D18: 65798.394 | P18: 2013 | Q18: 9300.4543 | R18: 26831.811 | S18: 41159.998
A19: 2014 | B19: 38743.757 | C19: 58386.843 | P19: 2014 | Q19: 9235.008 | R19: 26495.238
A20: 2015 | B20: 43013.271 | P20: 2015 | Q20: 9643.9885
B24: Target - Direct Accident Year Case Reported Loss Development Factors | Q24: Target - Direct Accident Year Paid Loss Development Factors
B25: INDEMNITY | Q25: INDEMNITY
B26: 12 | C26: 24 | D26: 36 | E26: 48 | F26: 60 | G26: 72 | H26: 84 | I26: 96 | J26: 108 | K26: 120 | L26: 132 | M26: 144 | N26: 156 | Q26: 12 | R26: 24 | S26: 36 | T26: 48 | U26: 60 | V26: 72 | W26: 84 | X26: 96 | Y26: 108 | Z26: 120 | AA26: 132 | AB26: 144 | AC26: 156
A27: Accident | B27: to | C27: to | D27: to | E27: to | F27: to | G27: to | H27: to | I27: to | J27: to | K27: to | L27: to | M27: to | N27: to | P27: Accident | Q27: to | R27: to | S27: to | T27: to | U27: to | V27: to | W27: to | X27: to | Y27: to | Z27: to | AA27: to | AB27: to | AC27: to
A28: Year | B28: 24 | C28: 36 | D28: 48 | E28: 60 | F28: 72 | G28: 84 | H28: 96 | I28: 108 | J28: 120 | K28: 132 | L28: 144 | M28: 156 | N28: Ultimate | P28: Year | Q28: 24 | R28: 36 | S28: 48 | T28: 60 | U28: 72 | V28: 84 | W28: 96 | X28: 108 | Y28: 120 | Z28: 132 | AA28: 144 | AB28: 156 | AC28: Ultimate
A30: =A8 -> 2003 | I30: =IFERROR(J8/I8,1) -> 1.0195499 | J30: =IFERROR(K8/J8,1) -> 1.0095914 | K30: =IFERROR(L8/K8,1) -> 0.98105475 | L30: =IFERROR(M8/L8,1) -> 1.0191736 | M30: =IFERROR(N8/M8,1) -> 0.99009901 | P30: =P8 -> 2003 | X30: =IFERROR(Y8/X8,1) -> 1.0254764 | Y30: =IFERROR(Z8/Y8,1) -> 1.0229286 | Z30: =IFERROR(AA8/Z8,1) -> 1 | AA30: =IFERROR(AB8/AA8,1) -> 1.0214605 | AB30: =IFERROR(AC8/AB8,1) -> 1.0069987
A31: =A9 -> 2004 | H31: =IFERROR(I9/H9,1) -> 0.993 | I31: =IFERROR(J9/I9,1) -> 1.0471903 | J31: =IFERROR(K9/J9,1) -> 1.0096535 | K31: =IFERROR(L9/K9,1) -> 1.0252053 | L31: =IFERROR(M9/L9,1) -> 0.99174422 | P31: =P9 -> 2004 | W31: =IFERROR(X9/W9,1) -> 1.015 | X31: =IFERROR(Y9/X9,1) -> 1.0373627 | Y31: =IFERROR(Z9/Y9,1) -> 1.0142946 | Z31: =IFERROR(AA9/Z9,1) -> 1.0353968 | AA31: =IFERROR(AB9/AA9,1) -> 1.0193841
A32: =A10 -> 2005 | G32: =IFERROR(H10/G10,1) -> 0.992 | H32: =IFERROR(I10/H10,1) -> 0.998 | I32: =IFERROR(J10/I10,1) -> 0.99345896 | J32: =IFERROR(K10/J10,1) -> 1.0203074 | K32: =IFERROR(L10/K10,1) -> 0.99410821 | P32: =P10 -> 2005 | V32: =IFERROR(W10/V10,1) -> 1.03 | W32: =IFERROR(X10/W10,1) -> 1.022 | X32: =IFERROR(Y10/X10,1) -> 1.0034875 | Y32: =IFERROR(Z10/Y10,1) -> 1.0263355 | Z32: =IFERROR(AA10/Z10,1) -> 1.0115206
A33: =A11 -> 2006 | F33: =IFERROR(G11/F11,1) -> 0.991 | G33: =IFERROR(H11/G11,1) -> 0.987 | H33: =IFERROR(I11/H11,1) -> 1.003 | I33: =IFERROR(J11/I11,1) -> 1.0064588 | J33: =IFERROR(K11/J11,1) -> 0.98995382 | P33: =P11 -> 2006 | U33: =IFERROR(V11/U11,1) -> 1.06 | V33: =IFERROR(W11/V11,1) -> 1.032 | W33: =IFERROR(X11/W11,1) -> 1.025 | X33: =IFERROR(Y11/X11,1) -> 1.0235685 | Y33: =IFERROR(Z11/Y11,1) -> 1.0109163
A34: =A12 -> 2007 | E34: =IFERROR(F12/E12,1) -> 1.001 | F34: =IFERROR(G12/F12,1) -> 0.995 | G34: =IFERROR(H12/G12,1) -> 1.003 | H34: =IFERROR(I12/H12,1) -> 0.99 | I34: =IFERROR(J12/I12,1) -> 0.99448479 | P34: =P12 -> 2007 | T34: =IFERROR(U12/T12,1) -> 1.115 | U34: =IFERROR(V12/U12,1) -> 1.066 | V34: =IFERROR(W12/V12,1) -> 1.04 | W34: =IFERROR(X12/W12,1) -> 1.017 | X34: =IFERROR(Y12/X12,1) -> 1.011722
A35: =A13 -> 2008 | D35: =IFERROR(E13/D13,1) -> 1.035 | E35: =IFERROR(F13/E13,1) -> 1.004 | F35: =IFERROR(G13/F13,1) -> 0.993 | G35: =IFERROR(H13/G13,1) -> 0.998 | H35: =IFERROR(I13/H13,1) -> 0.99 | P35: =P13 -> 2008 | S35: =IFERROR(T13/S13,1) -> 1.212 | T35: =IFERROR(U13/T13,1) -> 1.137 | U35: =IFERROR(V13/U13,1) -> 1.057 | V35: =IFERROR(W13/V13,1) -> 1.03 | W35: =IFERROR(X13/W13,1) -> 1.015
A36: =A14 -> 2009 | C36: =IFERROR(D14/C14,1) -> 1.099 | D36: =IFERROR(E14/D14,1) -> 1.033 | E36: =IFERROR(F14/E14,1) -> 0.996 | F36: =IFERROR(G14/F14,1) -> 0.995 | G36: =IFERROR(H14/G14,1) -> 0.996 | P36: =P14 -> 2009 | R36: =IFERROR(S14/R14,1) -> 1.508 | S36: =IFERROR(T14/S14,1) -> 1.236 | T36: =IFERROR(U14/T14,1) -> 1.118 | U36: =IFERROR(V14/U14,1) -> 1.061 | V36: =IFERROR(W14/V14,1) -> 1.027
A37: =A15 -> 2010 | B37: =IFERROR(C15/B15,1) -> 1.319 | C37: =IFERROR(D15/C15,1) -> 1.11 | D37: =IFERROR(E15/D15,1) -> 1.035 | E37: =IFERROR(F15/E15,1) -> 0.996 | F37: =IFERROR(G15/F15,1) -> 1.002 | P37: =P15 -> 2010 | Q37: =IFERROR(R15/Q15,1) -> 2.657 | R37: =IFERROR(S15/R15,1) -> 1.55 | S37: =IFERROR(T15/S15,1) -> 1.23 | T37: =IFERROR(U15/T15,1) -> 1.117 | U37: =IFERROR(V15/U15,1) -> 1.06
A38: =A16 -> 2011 | B38: =IFERROR(C16/B16,1) -> 1.368 | C38: =IFERROR(D16/C16,1) -> 1.113 | D38: =IFERROR(E16/D16,1) -> 1.028 | E38: =IFERROR(F16/E16,1) -> 1.009 | P38: =P16 -> 2011 | Q38: =IFERROR(R16/Q16,1) -> 2.735 | R38: =IFERROR(S16/R16,1) -> 1.546 | S38: =IFERROR(T16/S16,1) -> 1.236 | T38: =IFERROR(U16/T16,1) -> 1.115
A39: =A17 -> 2012 | B39: =IFERROR(C17/B17,1) -> 1.4766573 | C39: =IFERROR(D17/C17,1) -> 1.144939 | D39: =IFERROR(E17/D17,1) -> 1.0341527 | P39: =P17 -> 2012 | Q39: =IFERROR(R17/Q17,1) -> 3.2655377 | R39: =IFERROR(S17/R17,1) -> 1.5543194 | S39: =IFERROR(T17/S17,1) -> 1.2361905
A40: =A18 -> 2013 | B40: =IFERROR(C18/B18,1) -> 1.345 | C40: =IFERROR(D18/C18,1) -> 1.149 | P40: =P18 -> 2013 | Q40: =IFERROR(R18/Q18,1) -> 2.885 | R40: =IFERROR(S18/R18,1) -> 1.534
A41: =A19 -> 2014 | B41: =IFERROR(C19/B19,1) -> 1.507 | P41: =P19 -> 2014 | Q41: =IFERROR(R19/Q19,1) -> 2.869
A43: Incremental Averages | P43: Incremental Averages
A44: 2 Year | B44: =AVERAGE(B40:B41) -> 1.426 | C44: =AVERAGE(C39:C40) -> 1.1469695 | D44: =AVERAGE(D38:D39) -> 1.0310763 | E44: =AVERAGE(E37:E38) -> 1.0025 | F44: =AVERAGE(F36:F37) -> 0.9985 | G44: =AVERAGE(G35:G36) -> 0.997 | H44: =AVERAGE(H34:H35) -> 0.99 | I44: =AVERAGE(I33:I34) -> 1.0004718 | J44: =AVERAGE(J32:J33) -> 1.0051306 | K44: =AVERAGE(K31:K32) -> 1.0096568 | L44: =AVERAGE(L30:L31) -> 1.0054589 | M44: =M$48 -> 0.99009901 | P44: 2 Year | Q44: =AVERAGE(Q40:Q41) -> 2.877 | R44: =AVERAGE(R39:R40) -> 1.5441597 | S44: =AVERAGE(S38:S39) -> 1.2360953 | T44: =AVERAGE(T37:T38) -> 1.116 | U44: =AVERAGE(U36:U37) -> 1.0605 | V44: =AVERAGE(V35:V36) -> 1.0285 | W44: =AVERAGE(W34:W35) -> 1.016 | X44: =AVERAGE(X34:X35) -> 1.011722 | Y44: =AVERAGE(Y32:Y33) -> 1.0186259 | Z44: =AVERAGE(Z31:Z32) -> 1.0234587 | AA44: =AVERAGE(AA30:AA31) -> 1.0204223 | AB44: =AB$48 -> 1.0069987
A45: 3 Year | B45: =AVERAGE(B39:B41) -> 1.4428858 | C45: =AVERAGE(C38:C40) -> 1.1356463 | D45: =AVERAGE(D37:D39) -> 1.0323842 | E45: =AVERAGE(E36:E38) -> 1.0003333 | F45: =AVERAGE(F35:F37) -> 0.99666667 | G45: =AVERAGE(G34:G36) -> 0.999 | H45: =AVERAGE(H33:H35) -> 0.99433333 | I45: =AVERAGE(I32:I34) -> 0.99813418 | J45: =AVERAGE(J31:J33) -> 1.0066382 | K45: =AVERAGE(K30:K32) -> 1.0001228 | L45: =L$48 -> 1.0054589 | M45: =M$48 -> 0.99009901 | P45: 3 Year | Q45: =AVERAGE(Q39:Q41) -> 3.0065126 | R45: =AVERAGE(R38:R40) -> 1.5447731 | S45: =AVERAGE(S37:S39) -> 1.2340635 | T45: =AVERAGE(T36:T38) -> 1.1166667 | U45: =AVERAGE(U35:U37) -> 1.0593333 | V45: =AVERAGE(V34:V36) -> 1.0323333 | W45: =AVERAGE(W33:W35) -> 1.019 | X45: =AVERAGE(X33:X35) -> 1.0176452 | Y45: =AVERAGE(Y31:Y33) -> 1.0171821 | Z45: =AVERAGE(Z30:Z32) -> 1.0156392 | AA45: =AA$48 -> 1.0204223 | AB45: =AB$48 -> 1.0069987
A46: 4 Year | B46: =AVERAGE(B38:B41) -> 1.4241643 | C46: =AVERAGE(C37:C40) -> 1.1292347 | D46: =AVERAGE(D36:D39) -> 1.0325382 | E46: =AVERAGE(E35:E38) -> 1.00125 | F46: =AVERAGE(F34:F37) -> 0.99625 | G46: =AVERAGE(G33:G36) -> 0.996 | H46: =AVERAGE(H32:H35) -> 0.99525 | I46: =AVERAGE(I31:I34) -> 1.0103982 | J46: =AVERAGE(J30:J33) -> 1.0073765 | K46: =K$48 -> 1.0001228 | L46: =L$48 -> 1.0054589 | M46: =M$48 -> 0.99009901 | P46: 4 Year | Q46: =AVERAGE(Q38:Q41) -> 2.9386344 | R46: =AVERAGE(R37:R40) -> 1.5460798 | S46: =AVERAGE(S36:S39) -> 1.2345476 | T46: =AVERAGE(T35:T38) -> 1.12175 | U46: =AVERAGE(U34:U37) -> 1.061 | V46: =AVERAGE(V33:V36) -> 1.03225 | W46: =AVERAGE(W32:W35) -> 1.01975 | X46: =AVERAGE(X32:X35) -> 1.012926 | Y46: =AVERAGE(Y30:Y33) -> 1.0186187 | Z46: =Z$48 -> 1.0156392 | AA46: =AA$48 -> 1.0204223 | AB46: =AB$48 -> 1.0069987
A47: 5 Year | B47: =AVERAGE(B37:B41) -> 1.4031315 | C47: =AVERAGE(C36:C40) -> 1.1231878 | D47: =AVERAGE(D35:D39) -> 1.0330305 | E47: =AVERAGE(E34:E38) -> 1.0012 | F47: =AVERAGE(F33:F37) -> 0.9952 | G47: =AVERAGE(G32:G36) -> 0.9952 | H47: =AVERAGE(H31:H35) -> 0.9948 | I47: =AVERAGE(I30:I34) -> 1.0122285 | J47: =J$48 -> 1.0073765 | K47: =K$48 -> 1.0001228 | L47: =L$48 -> 1.0054589 | M47: =M$48 -> 0.99009901 | P47: 5 Year | Q47: =AVERAGE(Q37:Q41) -> 2.8823075 | R47: =AVERAGE(R36:R40) -> 1.5384639 | S47: =AVERAGE(S35:S39) -> 1.2300381 | T47: =AVERAGE(T34:T38) -> 1.1204 | U47: =AVERAGE(U33:U37) -> 1.0608 | V47: =AVERAGE(V32:V36) -> 1.0318 | W47: =AVERAGE(W31:W35) -> 1.0188 | X47: =AVERAGE(X30:X34) -> 1.0203234 | Y47: =Y$48 -> 1.0186187 | Z47: =Z$48 -> 1.0156392 | AA47: =AA$48 -> 1.0204223 | AB47: =AB$48 -> 1.0069987
A48: All Year | B48: =AVERAGE(B30:B42) -> 1.4031315 | C48: =AVERAGE(C30:C42) -> 1.1231878 | D48: =AVERAGE(D30:D42) -> 1.0330305 | E48: =AVERAGE(E30:E42) -> 1.0012 | F48: =AVERAGE(F30:F42) -> 0.9952 | G48: =AVERAGE(G30:G42) -> 0.9952 | H48: =AVERAGE(H30:H42) -> 0.9948 | I48: =AVERAGE(I30:I42) -> 1.0122285 | ... M48: =AVERAGE(M30:M42) -> 0.99009901 | P48: All Year | Q48: =AVERAGE(Q30:Q42) -> 2.8823075 | R48: =AVERAGE(R30:R42) -> 1.5384639 | S48: =AVERAGE(S30:S42) -> 1.2300381 | T48: =AVERAGE(T30:T42) -> 1.1204 | U48: =AVERAGE(U30:U42) -> 1.0608 | V48: =AVERAGE(V30:V42) -> 1.0318 | W48: =AVERAGE(W30:W42) -> 1.0188 | X48: =AVERAGE(X30:X42) -> 1.0203234 | ... AB48: =AVERAGE(AB30:AB42) -> 1.0069987
...

Sheet Base_Med_Tri
B2: Direct Accident Year Case Reported Loss Development Factors | Q2: Direct Accident Year Paid Loss Development Factors
B3: MEDICAL in $Thousands | Q3: MEDICAL in $Thousands
A5: Accident | P5: Accident
A6: Year | B6: 12 | C6: 24 | D6: 36 | E6: 48 | F6: 60 | G6: 72 | H6: 84 | I6: 96 | J6: 108 | K6: 120 | L6: 132 | M6: 144 | N6: 156 | P6: Year | Q6: 12 | R6: 24 | S6: 36 | T6: 48 | U6: 60 | V6: 72 | W6: 84 | X6: 96 | Y6: 108 | Z6: 120 | AA6: 132 | AB6: 144 | AC6: 156
A8: 2003 | I8: 68261.871 | J8: 72177.999 | K8: 74888.329 | L8: 74074.116 | M8: 75563.161 | N8: 74815.011 | P8: 2003 | X8: 64887.26 | Y8: 67428.993 | Z8: 69896.2 | AA8: 70623.512 | AB8: 72993.882 | AC8: 74815.011
A9: 2004 | H9: 73662.527 | I9: 73957.177 | J9: 76212.65 | K9: 76026.545 | L9: 77661.513 | M9: 76989.422 | P9: 2004 | W9: 69515.802 | X9: 69724.35 | Y9: 71553.608 | Z9: 71797.956 | AA9: 73621.339 | AB9: 74371.647
A10: 2005 | G10: 72588.761 | H10: 71790.285 | I10: 71359.543 | J10: 74329.475 | K10: 78579.887 | L10: 78953.403 | P10: 2005 | V10: 68243.937 | W10: 68585.157 | X10: 68928.082 | Y10: 70234.062 | Z10: 73194.215 | AA10: 75063.219
A11: 2006 | F11: 76631.248 | G11: 76171.46 | H11: 75028.888 | I11: 75854.206 | J11: 78129.98 | K11: 78698.088 | P11: 2006 | U11: 69548.414 | V11: 70661.189 | W11: 71085.156 | X11: 71653.837 | Y11: 73177.206 | Z11: 73809.197
A12: 2007 | E12: 80418.098 | F12: 79292.245 | G12: 78420.03 | H12: 77086.89 | I12: 76855.629 | J12: 78151.254 | P12: 2007 | T12: 69856.704 | U12: 71393.551 | V12: 72036.093 | W12: 72252.202 | X12: 72468.958 | Y12: 73620.281
A13: 2008 | D13: 79507.552 | E13: 79030.507 | F13: 77766.019 | G13: 76988.359 | H13: 75987.51 | I13: 75759.548 | P13: 2008 | S13: 65954.209 | T13: 69185.965 | U13: 70638.87 | V13: 71203.981 | W13: 71631.205 | X13: 71917.73
A14: 2009 | C14: 82756.275 | D14: 82839.031 | E14: 83087.548 | F14: 81758.147 | G14: 81104.082 | H14: 79968.625 | P14: 2009 | R14: 63478.038 | S14: 70968.446 | T14: 73736.216 | U14: 74915.995 | V14: 75365.491 | W14: 75516.222
A15: 2010 | B15: 66169.732 | C15: 81984.298 | D15: 83541.999 | E15: 82706.579 | F15: 80638.915 | G15: 79772.033 | P15: 2010 | Q15: 32446.915 | R15: 62070.948 | S15: 69395.32 | T15: 72240.528 | U15: 73324.136 | V15: 73984.053
A16: 2011 | B16: 67818.652 | C16: 85654.957 | D16: 86083.232 | E16: 83845.068 | F16: 83509.688 | P16: 2011 | Q16: 33008.852 | R16: 64598.323 | S16: 71962.532 | T16: 74625.145 | U16: 75968.398
A17: 2012 | B17: 70617.106 | C17: 96200.765 | D17: 101671.56 | E17: 99408.546 | P17: 2012 | Q17: 34990.76 | R17: 71657.398 | S17: 81322.999 | T17: 88998.627
A18: 2013 | B18: 65448.894 | C18: 80633.038 | D18: 82729.497 | P18: 2013 | Q18: 31785.474 | R18: 62331.315 | S18: 69374.753
A19: 2014 | B19: 63580.214 | C19: 84816.006 | P19: 2014 | Q19: 33130.663 | R19: 64406.01
A20: 2015 | B20: 66114.319 | P20: 2015 | Q20: 32876.614
B24: Target - Direct Accident Year Case Reported Loss Development Factors | Q24: Target - Direct Accident Year Paid Loss Development Factors
B25: MEDICAL | Q25: MEDICAL
B26: 12 | C26: 24 | D26: 36 | E26: 48 | F26: 60 | G26: 72 | H26: 84 | I26: 96 | J26: 108 | K26: 120 | L26: 132 | M26: 144 | N26: 156 | Q26: 12 | R26: 24 | S26: 36 | T26: 48 | U26: 60 | V26: 72 | W26: 84 | X26: 96 | Y26: 108 | Z26: 120 | AA26: 132 | AB26: 144 | AC26: 156
A27: Accident | B27: to | C27: to | D27: to | E27: to | F27: to | G27: to | H27: to | I27: to | J27: to | K27: to | L27: to | M27: to | N27: to | P27: Accident | Q27: to | R27: to | S27: to | T27: to | U27: to | V27: to | W27: to | X27: to | Y27: to | Z27: to | AA27: to | AB27: to | AC27: to
A28: Year | B28: 24 | C28: 36 | D28: 48 | E28: 60 | F28: 72 | G28: 84 | H28: 96 | I28: 108 | J28: 120 | K28: 132 | L28: 144 | M28: 156 | N28: Ultimate | P28: Year | Q28: 24 | R28: 36 | S28: 48 | T28: 60 | U28: 72 | V28: 84 | W28: 96 | X28: 108 | Y28: 120 | Z28: 132 | AA28: 144 | AB28: 156 | AC28: Ultimate
A30: =A8 -> 2003 | I30: =IFERROR(J8/I8,1) -> 1.0573692 | J30: =IFERROR(K8/J8,1) -> 1.0375506 | K30: =IFERROR(L8/K8,1) -> 0.98912764 | L30: =IFERROR(M8/L8,1) -> 1.0201021 | M30: =IFERROR(N8/M8,1) -> 0.99009901 | P30: =P8 -> 2003 | X30: =IFERROR(Y8/X8,1) -> 1.0391715 | Y30: =IFERROR(Z8/Y8,1) -> 1.0365897 | Z30: =IFERROR(AA8/Z8,1) -> 1.0104056 | AA30: =IFERROR(AB8/AA8,1) -> 1.0335635 | AB30: =IFERROR(AC8/AB8,1) -> 1.0249491
A31: =A9 -> 2004 | H31: =IFERROR(I9/H9,1) -> 1.004 | I31: =IFERROR(J9/I9,1) -> 1.030497 | J31: =IFERROR(K9/J9,1) -> 0.99755807 | K31: =IFERROR(L9/K9,1) -> 1.0215052 | L31: =IFERROR(M9/L9,1) -> 0.99134588 | P31: =P9 -> 2004 | W31: =IFERROR(X9/W9,1) -> 1.003 | X31: =IFERROR(Y9/X9,1) -> 1.0262356 | Y31: =IFERROR(Z9/Y9,1) -> 1.0034149 | Z31: =IFERROR(AA9/Z9,1) -> 1.025396 | AA31: =IFERROR(AB9/AA9,1) -> 1.0101914
A32: =A10 -> 2005 | G32: =IFERROR(H10/G10,1) -> 0.989 | H32: =IFERROR(I10/H10,1) -> 0.994 | I32: =IFERROR(J10/I10,1) -> 1.0416193 | J32: =IFERROR(K10/J10,1) -> 1.0571834 | K32: =IFERROR(L10/K10,1) -> 1.0047533 | P32: =P10 -> 2005 | V32: =IFERROR(W10/V10,1) -> 1.005 | W32: =IFERROR(X10/W10,1) -> 1.005 | X32: =IFERROR(Y10/X10,1) -> 1.018947 | Y32: =IFERROR(Z10/Y10,1) -> 1.042147 | Z32: =IFERROR(AA10/Z10,1) -> 1.0255349
A33: =A11 -> 2006 | F33: =IFERROR(G11/F11,1) -> 0.994 | G33: =IFERROR(H11/G11,1) -> 0.985 | H33: =IFERROR(I11/H11,1) -> 1.011 | I33: =IFERROR(J11/I11,1) -> 1.0300019 | J33: =IFERROR(K11/J11,1) -> 1.0072713 | P33: =P11 -> 2006 | U33: =IFERROR(V11/U11,1) -> 1.016 | V33: =IFERROR(W11/V11,1) -> 1.006 | W33: =IFERROR(X11/W11,1) -> 1.008 | X33: =IFERROR(Y11/X11,1) -> 1.0212601 | Y33: =IFERROR(Z11/Y11,1) -> 1.0086364
A34: =A12 -> 2007 | E34: =IFERROR(F12/E12,1) -> 0.986 | F34: =IFERROR(G12/F12,1) -> 0.989 | G34: =IFERROR(H12/G12,1) -> 0.983 | H34: =IFERROR(I12/H12,1) -> 0.997 | I34: =IFERROR(J12/I12,1) -> 1.0168579 | P34: =P12 -> 2007 | T34: =IFERROR(U12/T12,1) -> 1.022 | U34: =IFERROR(V12/U12,1) -> 1.009 | V34: =IFERROR(W12/V12,1) -> 1.003 | W34: =IFERROR(X12/W12,1) -> 1.003 | X34: =IFERROR(Y12/X12,1) -> 1.0158871
A35: =A13 -> 2008 | D35: =IFERROR(E13/D13,1) -> 0.994 | E35: =IFERROR(F13/E13,1) -> 0.984 | F35: =IFERROR(G13/F13,1) -> 0.99 | G35: =IFERROR(H13/G13,1) -> 0.987 | H35: =IFERROR(I13/H13,1) -> 0.997 | P35: =P13 -> 2008 | S35: =IFERROR(T13/S13,1) -> 1.049 | T35: =IFERROR(U13/T13,1) -> 1.021 | U35: =IFERROR(V13/U13,1) -> 1.008 | V35: =IFERROR(W13/V13,1) -> 1.006 | W35: =IFERROR(X13/W13,1) -> 1.004
A36: =A14 -> 2009 | C36: =IFERROR(D14/C14,1) -> 1.001 | D36: =IFERROR(E14/D14,1) -> 1.003 | E36: =IFERROR(F14/E14,1) -> 0.984 | F36: =IFERROR(G14/F14,1) -> 0.992 | G36: =IFERROR(H14/G14,1) -> 0.986 | P36: =P14 -> 2009 | R36: =IFERROR(S14/R14,1) -> 1.118 | S36: =IFERROR(T14/S14,1) -> 1.039 | T36: =IFERROR(U14/T14,1) -> 1.016 | U36: =IFERROR(V14/U14,1) -> 1.006 | V36: =IFERROR(W14/V14,1) -> 1.002
A37: =A15 -> 2010 | B37: =IFERROR(C15/B15,1) -> 1.239 | C37: =IFERROR(D15/C15,1) -> 1.019 | D37: =IFERROR(E15/D15,1) -> 0.99 | E37: =IFERROR(F15/E15,1) -> 0.975 | F37: =IFERROR(G15/F15,1) -> 0.98924983 | P37: =P15 -> 2010 | Q37: =IFERROR(R15/Q15,1) -> 1.913 | R37: =IFERROR(S15/R15,1) -> 1.118 | S37: =IFERROR(T15/S15,1) -> 1.041 | T37: =IFERROR(U15/T15,1) -> 1.015 | U37: =IFERROR(V15/U15,1) -> 1.009
A38: =A16 -> 2011 | B38: =IFERROR(C16/B16,1) -> 1.263 | C38: =IFERROR(D16/C16,1) -> 1.005 | D38: =IFERROR(E16/D16,1) -> 0.974 | E38: =IFERROR(F16/E16,1) -> 0.996 | P38: =P16 -> 2011 | Q38: =IFERROR(R16/Q16,1) -> 1.957 | R38: =IFERROR(S16/R16,1) -> 1.114 | S38: =IFERROR(T16/S16,1) -> 1.037 | T38: =IFERROR(U16/T16,1) -> 1.018
A39: =A17 -> 2012 | B39: =IFERROR(C17/B17,1) -> 1.362287 | C39: =IFERROR(D17/C17,1) -> 1.0568685 | D39: =IFERROR(E17/D17,1) -> 0.97774191 | P39: =P17 -> 2012 | Q39: =IFERROR(R17/Q17,1) -> 2.0478949 | R39: =IFERROR(S17/R17,1) -> 1.1348863 | S39: =IFERROR(T17/S17,1) -> 1.0943845
A40: =A18 -> 2013 | B40: =IFERROR(C18/B18,1) -> 1.232 | C40: =IFERROR(D18/C18,1) -> 1.026 | P40: =P18 -> 2013 | Q40: =IFERROR(R18/Q18,1) -> 1.961 | R40: =IFERROR(S18/R18,1) -> 1.113
A41: =A19 -> 2014 | B41: =IFERROR(C19/B19,1) -> 1.334 | P41: =P19 -> 2014 | Q41: =IFERROR(R19/Q19,1) -> 1.944
A43: Incremental Averages | P43: Incremental Averages
A44: 2 Year | B44: =AVERAGE(B40:B41) -> 1.283 | C44: =AVERAGE(C39:C40) -> 1.0414343 | D44: =AVERAGE(D38:D39) -> 0.97587096 | E44: =AVERAGE(E37:E38) -> 0.9855 | F44: =AVERAGE(F36:F37) -> 0.99062491 | G44: =AVERAGE(G35:G36) -> 0.9865 | H44: =AVERAGE(H34:H35) -> 0.997 | I44: =AVERAGE(I33:I34) -> 1.0234299 | J44: =AVERAGE(J32:J33) -> 1.0322274 | K44: =AVERAGE(K31:K32) -> 1.0131293 | L44: =AVERAGE(L30:L31) -> 1.005724 | M44: =M$48 -> 0.99009901 | P44: 2 Year | Q44: =AVERAGE(Q40:Q41) -> 1.9525 | R44: =AVERAGE(R39:R40) -> 1.1239431 | S44: =AVERAGE(S38:S39) -> 1.0656922 | T44: =AVERAGE(T37:T38) -> 1.0165 | U44: =AVERAGE(U36:U37) -> 1.0075 | V44: =AVERAGE(V35:V36) -> 1.004 | W44: =AVERAGE(W34:W35) -> 1.0035 | X44: =AVERAGE(X34:X35) -> 1.0158871 | Y44: =AVERAGE(Y32:Y33) -> 1.0253917 | Z44: =AVERAGE(Z31:Z32) -> 1.0254654 | AA44: =AVERAGE(AA30:AA31) -> 1.0218775 | AB44: =AB$48 -> 1.0249491
A45: 3 Year | B45: =AVERAGE(B39:B41) -> 1.309429 | C45: =AVERAGE(C38:C40) -> 1.0292895 | D45: =AVERAGE(D37:D39) -> 0.98058064 | E45: =AVERAGE(E36:E38) -> 0.985 | F45: =AVERAGE(F35:F37) -> 0.99041661 | G45: =AVERAGE(G34:G36) -> 0.98533333 | H45: =AVERAGE(H33:H35) -> 1.0016667 | I45: =AVERAGE(I32:I34) -> 1.029493 | J45: =AVERAGE(J31:J33) -> 1.0206709 | K45: =AVERAGE(K30:K32) -> 1.0051287 | L45: =L$48 -> 1.005724 | M45: =M$48 -> 0.99009901 | P45: 3 Year | Q45: =AVERAGE(Q39:Q41) -> 1.9842983 | R45: =AVERAGE(R38:R40) -> 1.1206288 | S45: =AVERAGE(S37:S39) -> 1.0574615 | T45: =AVERAGE(T36:T38) -> 1.0163333 | U45: =AVERAGE(U35:U37) -> 1.0076667 | V45: =AVERAGE(V34:V36) -> 1.0036667 | W45: =AVERAGE(W33:W35) -> 1.005 | X45: =AVERAGE(X33:X35) -> 1.0185736 | Y45: =AVERAGE(Y31:Y33) -> 1.0180661 | Z45: =AVERAGE(Z30:Z32) -> 1.0204455 | AA45: =AA$48 -> 1.0218775 | AB45: =AB$48 -> 1.0249491
A46: 4 Year | B46: =AVERAGE(B38:B41) -> 1.2978217 | C46: =AVERAGE(C37:C40) -> 1.0267171 | D46: =AVERAGE(D36:D39) -> 0.98618548 | E46: =AVERAGE(E35:E38) -> 0.98475 | F46: =AVERAGE(F34:F37) -> 0.99006246 | G46: =AVERAGE(G33:G36) -> 0.98525 | H46: =AVERAGE(H32:H35) -> 0.99975 | I46: =AVERAGE(I31:I34) -> 1.029744 | J46: =AVERAGE(J30:J33) -> 1.0248909 | K46: =K$48 -> 1.0051287 | L46: =L$48 -> 1.005724 | M46: =M$48 -> 0.99009901 | P46: 4 Year | Q46: =AVERAGE(Q38:Q41) -> 1.9774737 | R46: =AVERAGE(R37:R40) -> 1.1199716 | S46: =AVERAGE(S36:S39) -> 1.0528461 | T46: =AVERAGE(T35:T38) -> 1.0175 | U46: =AVERAGE(U34:U37) -> 1.008 | V46: =AVERAGE(V33:V36) -> 1.00425 | W46: =AVERAGE(W32:W35) -> 1.005 | X46: =AVERAGE(X32:X35) -> 1.0186981 | Y46: =AVERAGE(Y30:Y33) -> 1.022697 | Z46: =Z$48 -> 1.0204455 | AA46: =AA$48 -> 1.0218775 | AB46: =AB$48 -> 1.0249491
A47: 5 Year | B47: =AVERAGE(B37:B41) -> 1.2860574 | C47: =AVERAGE(C36:C40) -> 1.0215737 | D47: =AVERAGE(D35:D39) -> 0.98774838 | E47: =AVERAGE(E34:E38) -> 0.985 | F47: =AVERAGE(F33:F37) -> 0.99084997 | G47: =AVERAGE(G32:G36) -> 0.986 | H47: =AVERAGE(H31:H35) -> 1.0006 | I47: =AVERAGE(I30:I34) -> 1.0352691 | J47: =J$48 -> 1.0248909 | K47: =K$48 -> 1.0051287 | L47: =L$48 -> 1.005724 | M47: =M$48 -> 0.99009901 | P47: 5 Year | Q47: =AVERAGE(Q37:Q41) -> 1.964579 | R47: =AVERAGE(R36:R40) -> 1.1195773 | S47: =AVERAGE(S35:S39) -> 1.0520769 | T47: =AVERAGE(T34:T38) -> 1.0184 | U47: =AVERAGE(U33:U37) -> 1.0096 | V47: =AVERAGE(V32:V36) -> 1.0044 | W47: =AVERAGE(W31:W35) -> 1.0046 | X47: =AVERAGE(X30:X34) -> 1.0243003 | Y47: =Y$48 -> 1.022697 | Z47: =Z$48 -> 1.0204455 | AA47: =AA$48 -> 1.0218775 | AB47: =AB$48 -> 1.0249491
A48: All Year | B48: =AVERAGE(B30:B42) -> 1.2860574 | C48: =AVERAGE(C30:C42) -> 1.0215737 | D48: =AVERAGE(D30:D42) -> 0.98774838 | E48: =AVERAGE(E30:E42) -> 0.985 | F48: =AVERAGE(F30:F42) -> 0.99084997 | G48: =AVERAGE(G30:G42) -> 0.986 | H48: =AVERAGE(H30:H42) -> 1.0006 | I48: =AVERAGE(I30:I42) -> 1.0352691 | ... M48: =AVERAGE(M30:M42) -> 0.99009901 | P48: All Year | Q48: =AVERAGE(Q30:Q42) -> 1.964579 | R48: =AVERAGE(R30:R42) -> 1.1195773 | S48: =AVERAGE(S30:S42) -> 1.0520769 | T48: =AVERAGE(T30:T42) -> 1.0184 | U48: =AVERAGE(U30:U42) -> 1.0096 | V48: =AVERAGE(V30:V42) -> 1.0044 | W48: =AVERAGE(W30:W42) -> 1.0046 | X48: =AVERAGE(X30:X42) -> 1.0243003 | ... AB48: =AVERAGE(AB30:AB42) -> 1.0249491
...

Sheet % of Ult
B3: Percent Paid | D3: Percent Reported
A4: Age | B4: Indemnity | C4: Medical | D4: Indemnity | E4: Medical
B5: Ind Paid | C5: Med Paid | D5: Ind Rep | E5: Med Rep
A6: 12 | B6: =1/HLOOKUP($A6,Base_Indem_Tri!$Q$6:$AC$57,52,FALSE) -> 1 | C6: =1/HLOOKUP($A6,Base_Med_Tri!$Q$6:$AC$57,52,FALSE) -> 1 | D6: =1/HLOOKUP($A6,Base_Indem_Tri!$B$6:$N$57,52,FALSE) -> 1 | E6: =1/HLOOKUP($A6,Base_Med_Tri!$B$6:$N$57,52,FALSE) -> 1
A7: =+A6+12 -> 24 | B7: =1/HLOOKUP($A7,Base_Indem_Tri!$Q$6:$AC$57,52,FALSE) -> 1 | C7: =1/HLOOKUP($A7,Base_Med_Tri!$Q$6:$AC$57,52,FALSE) -> 1 | D7: =1/HLOOKUP($A7,Base_Indem_Tri!$B$6:$N$57,52,FALSE) -> 1 | E7: =1/HLOOKUP($A7,Base_Med_Tri!$B$6:$N$57,52,FALSE) -> 1
A8: =+A7+12 -> 36 | B8: =1/HLOOKUP($A8,Base_Indem_Tri!$Q$6:$AC$57,52,FALSE) -> 1 | C8: =1/HLOOKUP($A8,Base_Med_Tri!$Q$6:$AC$57,52,FALSE) -> 1 | D8: =1/HLOOKUP($A8,Base_Indem_Tri!$B$6:$N$57,52,FALSE) -> 1 | E8: =1/HLOOKUP($A8,Base_Med_Tri!$B$6:$N$57,52,FALSE) -> 1
A9: =+A8+12 -> 48 | B9: =1/HLOOKUP($A9,Base_Indem_Tri!$Q$6:$AC$57,52,FALSE) -> 1 | C9: =1/HLOOKUP($A9,Base_Med_Tri!$Q$6:$AC$57,52,FALSE) -> 1 | D9: =1/HLOOKUP($A9,Base_Indem_Tri!$B$6:$N$57,52,FALSE) -> 1 | E9: =1/HLOOKUP($A9,Base_Med_Tri!$B$6:$N$57,52,FALSE) -> 1
A10: =+A9+12 -> 60 | B10: =1/HLOOKUP($A10,Base_Indem_Tri!$Q$6:$AC$57,52,FALSE) -> 1 | C10: =1/HLOOKUP($A10,Base_Med_Tri!$Q$6:$AC$57,52,FALSE) -> 1 | D10: =1/HLOOKUP($A10,Base_Indem_Tri!$B$6:$N$57,52,FALSE) -> 1 | E10: =1/HLOOKUP($A10,Base_Med_Tri!$B$6:$N$57,52,FALSE) -> 1
A11: =+A10+12 -> 72 | B11: =1/HLOOKUP($A11,Base_Indem_Tri!$Q$6:$AC$57,52,FALSE) -> 1 | C11: =1/HLOOKUP($A11,Base_Med_Tri!$Q$6:$AC$57,52,FALSE) -> 1 | D11: =1/HLOOKUP($A11,Base_Indem_Tri!$B$6:$N$57,52,FALSE) -> 1 | E11: =1/HLOOKUP($A11,Base_Med_Tri!$B$6:$N$57,52,FALSE) -> 1
A12: =+A11+12 -> 84 | B12: =1/HLOOKUP($A12,Base_Indem_Tri!$Q$6:$AC$57,52,FALSE) -> 1 | C12: =1/HLOOKUP($A12,Base_Med_Tri!$Q$6:$AC$57,52,FALSE) -> 1 | D12: =1/HLOOKUP($A12,Base_Indem_Tri!$B$6:$N$57,52,FALSE) -> 1 | E12: =1/HLOOKUP($A12,Base_Med_Tri!$B$6:$N$57,52,FALSE) -> 1
A13: =+A12+12 -> 96 | B13: =1/HLOOKUP($A13,Base_Indem_Tri!$Q$6:$AC$57,52,FALSE) -> 1 | C13: =1/HLOOKUP($A13,Base_Med_Tri!$Q$6:$AC$57,52,FALSE) -> 1 | D13: =1/HLOOKUP($A13,Base_Indem_Tri!$B$6:$N$57,52,FALSE) -> 1 | E13: =1/HLOOKUP($A13,Base_Med_Tri!$B$6:$N$57,52,FALSE) -> 1
A14: =+A13+12 -> 108 | B14: =1/HLOOKUP($A14,Base_Indem_Tri!$Q$6:$AC$57,52,FALSE) -> 1 | C14: =1/HLOOKUP($A14,Base_Med_Tri!$Q$6:$AC$57,52,FALSE) -> 1 | D14: =1/HLOOKUP($A14,Base_Indem_Tri!$B$6:$N$57,52,FALSE) -> 1 | E14: =1/HLOOKUP($A14,Base_Med_Tri!$B$6:$N$57,52,FALSE) -> 1
A15: =+A14+12 -> 120 | B15: =1/HLOOKUP($A15,Base_Indem_Tri!$Q$6:$AC$57,52,FALSE) -> 1 | C15: =1/HLOOKUP($A15,Base_Med_Tri!$Q$6:$AC$57,52,FALSE) -> 1 | D15: =1/HLOOKUP($A15,Base_Indem_Tri!$B$6:$N$57,52,FALSE) -> 1 | E15: =1/HLOOKUP($A15,Base_Med_Tri!$B$6:$N$57,52,FALSE) -> 1
A16: =+A15+12 -> 132 | B16: =1/HLOOKUP($A16,Base_Indem_Tri!$Q$6:$AC$57,52,FALSE) -> 1 | C16: =1/HLOOKUP($A16,Base_Med_Tri!$Q$6:$AC$57,52,FALSE) -> 1 | D16: =1/HLOOKUP($A16,Base_Indem_Tri!$B$6:$N$57,52,FALSE) -> 1 | E16: =1/HLOOKUP($A16,Base_Med_Tri!$B$6:$N$57,52,FALSE) -> 1
A17: =+A16+12 -> 144 | B17: =1/HLOOKUP($A17,Base_Indem_Tri!$Q$6:$AC$57,52,FALSE) -> 1 | C17: =1/HLOOKUP($A17,Base_Med_Tri!$Q$6:$AC$57,52,FALSE) -> 1 | D17: =1/HLOOKUP($A17,Base_Indem_Tri!$B$6:$N$57,52,FALSE) -> 1 | E17: =1/HLOOKUP($A17,Base_Med_Tri!$B$6:$N$57,52,FALSE) -> 1

Sheet Summary Freq&Sev
B2: TOU Insurance Company - Workers Compensation
B3: Development of Unpaid Claim Estimate | Y3: Reported Claim Development | AD3: Paid Loss Development | AI3: Paid Loss Development
B4: Indemnity + Medical | Y4: Reported Claims | AD4: Indemnity Severity | AI4: Medical Severity
O6: Unpaid Claim Estimate | Y6: Accident | Z6: Reported | AA6: Selected | AB6: Ultimate | AD6: Accident | AE6: Paid | AF6: Selected | AG6: Ultimate | AI6: Accident | AJ6: Paid | AK6: Selected | AL6: Ultimate
F7: Case | G7: Project Ultimate Claims | K7: Project Ultimate Loss Ratios | O7: IBNR | S7: Total Unpaid | Y7: Year | Z7: Claims | AA7: LDFs | AB7: Claims | AD7: Year | AE7: Severity | AF7: LDFs | AG7: Severity | AI7: Year | AJ7: Severity | AK7: LDFs | AL7: Severity
B8: Accident | C8: Earned | D8: ="Claims at 12/31/" & B24 -> Claims at 12/31/2015 | F8: Outstanding | G8: Loss Development | I8: Frequency/Severity | K8: Loss Development | M8: Frequency/Severity | O8: Loss Development | Q8: Frequency/Severity | S8: Loss Development | U8: Frequency/Severity | Y8: =Rep_Tri!A8 -> 2003 | Z8: =Rep_Tri!N8 -> 4353 | AA8: =Rep_Tri!$N$57 -> 1 | AB8: =AA8*Z8 -> 4353 | AD8: =Y8 -> 2003 | AE8: =Base_Indem_Sev!AC8 -> 16513 | AF8: =Base_Indem_Sev!$AC$57 -> 1 | AG8: =AE8*AF8 -> 16513 | AI8: =AD8 -> 2003 | AJ8: =Base_Med_Sev!AC8 -> 17187 | AK8: =Base_Med_Sev!$AC$57 -> 1 | AL8: =AJ8*AK8 -> 17187
B9: Year | C9: Premiums | D9: Paid | E9: Reported | F9: ="At 12/31/" & B24 -> At 12/31/2015 | G9: Paid | H9: Reported | I9: Paid | J9: Reported | K9: Paid | L9: Reported | M9: Paid | N9: Reported | O9: Paid | P9: Reported | Q9: Paid | R9: Reported | S9: Paid | T9: Reported | U9: Paid | V9: Reported | Y9: =Rep_Tri!A9 -> 2004 | Z9: =Rep_Tri!M9 -> 4175 | AA9: =Rep_Tri!M57 -> 1 | AB9: =AA9*Z9 -> 4175 | AD9: =Y9 -> 2004 | AE9: =Base_Indem_Sev!AB9 -> 17420.082 | AF9: =Base_Indem_Sev!AB57 -> 1 | AG9: =AE9*AF9 -> 17420.082 | AI9: =AD9 -> 2004 | AJ9: =Base_Med_Sev!AB9 -> 17813.568 | AK9: =Base_Med_Sev!AB57 -> 1 | AL9: =AJ9*AK9 -> 17813.568
B10: -1 | C10: =B10-1 -> -2 | D10: =C10-1 -> -3 | E10: =D10-1 -> -4 | F10: =E10-1 -> -5 | G10: =F10-1 -> -6 | H10: =G10-1 -> -7 | I10: =H10-1 -> -8 | J10: =I10-1 -> -9 | ... V10: =U10-1 -> -21 | Y10: =Rep_Tri!A10 -> 2005 | Z10: =Rep_Tri!L10 -> 4020 | AA10: =Rep_Tri!L57 -> 1 | AB10: =AA10*Z10 -> 4020 | AD10: =Y10 -> 2005 | AE10: =Base_Indem_Sev!AA10 -> 16877.782 | AF10: =Base_Indem_Sev!AA57 -> 1 | AG10: =AE10*AF10 -> 16877.782 | AI10: =AD10 -> 2005 | AJ10: =Base_Med_Sev!AA10 -> 18672.443 | AK10: =Base_Med_Sev!AA57 -> 1 | AL10: =AJ10*AK10 -> 18672.443
Y11: =Rep_Tri!A11 -> 2006 | Z11: =Rep_Tri!K11 -> 3755 | AA11: =Rep_Tri!K57 -> 1 | AB11: =AA11*Z11 -> 3755 | AD11: =Y11 -> 2006 | AE11: =Base_Indem_Sev!Z11 -> 17124.012 | AF11: =Base_Indem_Sev!Z57 -> 1 | AG11: =AE11*AF11 -> 17124.012 | AI11: =AD11 -> 2006 | AJ11: =Base_Med_Sev!Z11 -> 19656.244 | AK11: =Base_Med_Sev!Z57 -> 1 | AL11: =AJ11*AK11 -> 19656.244
B12: =Y8 -> 2003 | C12: =Summary!C11 -> 206600 | D12: =(AE8+AJ8)*Z8/1000 -> 146696.1 | E12: =(AE28+AJ28)*Z8/1000 -> 146696.1 | F12: =E12-D12 -> 0 | G12: =Summary!G11 -> 146696.1 | H12: =Summary!H11 -> 146696.1 | I12: =(AG8+AL8)*AB8/1000 -> 146696.1 | J12: =(AG28+AL28)*AB8/1000 -> 146696.1 | K12: =G12/$C12 -> 0.71004889 | L12: =H12/$C12 -> 0.71004889 | M12: =I12/$C12 -> 0.71004889 | N12: =J12/$C12 -> 0.71004889 | O12: =G12-$E12 -> 0 | P12: =H12-$E12 -> 0 | Q12: =I12-$E12 -> 0 | R12: =J12-$E12 -> 0 | S12: =$F12+O12 -> 0 | T12: =$F12+P12 -> 0 | U12: =$F12+Q12 -> 0 | V12: =$F12+R12 -> 0 | Y12: =Rep_Tri!A12 -> 2007 | Z12: =Rep_Tri!J12 -> 3586 | AA12: =Rep_Tri!J57 -> 1 | AB12: =AA12*Z12 -> 3586 | AD12: =Y12 -> 2007 | AE12: =Base_Indem_Sev!Y12 -> 17980.392 | AF12: =Base_Indem_Sev!Y57 -> 1 | AG12: =AE12*AF12 -> 17980.392 | AI12: =AD12 -> 2007 | AJ12: =Base_Med_Sev!Y12 -> 20529.917 | AK12: =Base_Med_Sev!Y57 -> 1 | AL12: =AJ12*AK12 -> 20529.917
B13: =Y9 -> 2004 | C13: =Summary!C12 -> 210500 | D13: =(AE9+AJ9)*Z9/1000 -> 147100.49 | E13: =(AE29+AJ29)*Z9/1000 -> 150959.65 | F13: =E13-D13 -> 3859.1597 | G13: =Summary!G12 -> 147100.49 | H13: =Summary!H12 -> 150959.65 | I13: =(AG9+AL9)*AB9/1000 -> 147100.49 | J13: =(AG29+AL29)*AB9/1000 -> 150959.65 | K13: =G13/$C13 -> 0.69881468 | L13: =H13/$C13 -> 0.71714798 | M13: =I13/$C13 -> 0.69881468 | N13: =J13/$C13 -> 0.71714798 | O13: =G13-$E13 -> -3859.1597 | P13: =H13-$E13 -> 0 | Q13: =I13-$E13 -> -3859.1597 | R13: =J13-$E13 -> 0 | S13: =$F13+O13 -> 0 | T13: =$F13+P13 -> 3859.1597 | U13: =$F13+Q13 -> 0 | V13: =$F13+R13 -> 3859.1597 | Y13: =Rep_Tri!A13 -> 2008 | Z13: =Rep_Tri!I13 -> 3507 | AA13: =Rep_Tri!I57 -> 1 | AB13: =AA13*Z13 -> 3507 | AD13: =Y13 -> 2008 | AE13: =Base_Indem_Sev!X13 -> 18741.819 | AF13: =Base_Indem_Sev!X57 -> 1 | AG13: =AE13*AF13 -> 18741.819 | AI13: =AD13 -> 2008 | AJ13: =Base_Med_Sev!X13 -> 20506.909 | AK13: =Base_Med_Sev!X57 -> 1 | AL13: =AJ13*AK13 -> 20506.909
B14: =Y10 -> 2005 | C14: =Summary!C13 -> 215000 | D14: =(AE10+AJ10)*Z10/1000 -> 142911.9 | E14: =(AE30+AJ30)*Z10/1000 -> 148987.14 | F14: =E14-D14 -> 6075.2383 | G14: =Summary!G13 -> 142911.9 | H14: =Summary!H13 -> 148987.14 | I14: =(AG10+AL10)*AB10/1000 -> 142911.9 | J14: =(AG30+AL30)*AB10/1000 -> 148987.14 | K14: =G14/$C14 -> 0.66470653 | L14: =H14/$C14 -> 0.69296345 | M14: =I14/$C14 -> 0.66470653 | N14: =J14/$C14 -> 0.69296345 | O14: =G14-$E14 -> -6075.2383 | P14: =H14-$E14 -> 0 | Q14: =I14-$E14 -> -6075.2383 | R14: =J14-$E14 -> 0 | S14: =$F14+O14 -> 0 | T14: =$F14+P14 -> 6075.2383 | U14: =$F14+Q14 -> 0 | V14: =$F14+R14 -> 6075.2383 | Y14: =Rep_Tri!A14 -> 2009 | Z14: =Rep_Tri!H14 -> 3356 | AA14: =Rep_Tri!H57 -> 1 | AB14: =AA14*Z14 -> 3356 | AD14: =Y14 -> 2009 | AE14: =Base_Indem_Sev!W14 -> 20295.265 | AF14: =Base_Indem_Sev!W57 -> 1 | AG14: =AE14*AF14 -> 20295.265 | AI14: =AD14 -> 2009 | AJ14: =Base_Med_Sev!W14 -> 22501.854 | AK14: =Base_Med_Sev!W57 -> 1 | AL14: =AJ14*AK14 -> 22501.854
B15: =Y11 -> 2006 | C15: =Summary!C14 -> 225300 | D15: =(AE11+AJ11)*Z11/1000 -> 138109.86 | E15: =(AE31+AJ31)*Z11/1000 -> 146037.76 | F15: =E15-D15 -> 7927.9005 | G15: =Summary!G14 -> 138109.86 | H15: =Summary!H14 -> 146037.76 | I15: =(AG11+AL11)*AB11/1000 -> 138109.86 | J15: =(AG31+AL31)*AB11/1000 -> 146037.76 | K15: =G15/$C15 -> 0.61300426 | L15: =H15/$C15 -> 0.64819246 | M15: =I15/$C15 -> 0.61300426 | N15: =J15/$C15 -> 0.64819246 | O15: =G15-$E15 -> -7927.9005 | P15: =H15-$E15 -> 0 | Q15: =I15-$E15 -> -7927.9005 | R15: =J15-$E15 -> 0 | S15: =$F15+O15 -> 0 | T15: =$F15+P15 -> 7927.9005 | U15: =$F15+Q15 -> 0 | V15: =$F15+R15 -> 7927.9005 | Y15: =Rep_Tri!A15 -> 2010 | Z15: =Rep_Tri!G15 -> 3192 | AA15: =Rep_Tri!G57 -> 1 | AB15: =AA15*Z15 -> 3192 | AD15: =Y15 -> 2010 | AE15: =Base_Indem_Sev!V15 -> 19575.563 | AF15: =Base_Indem_Sev!V57 -> 1 | AG15: =AE15*AF15 -> 19575.563 | AI15: =AD15 -> 2010 | AJ15: =Base_Med_Sev!V15 -> 23177.961 | AK15: =Base_Med_Sev!V57 -> 1 | AL15: =AJ15*AK15 -> 23177.961
B16: =Y12 -> 2007 | C16: =Summary!C15 -> 253500 | D16: =(AE12+AJ12)*Z12/1000 -> 138097.97 | E16: =(AE32+AJ32)*Z12/1000 -> 146506.69 | F16: =E16-D16 -> 8408.7198 | G16: =Summary!G15 -> 138097.97 | H16: =Summary!H15 -> 146506.69 | I16: =(AG12+AL12)*AB12/1000 -> 138097.97 | J16: =(AG32+AL32)*AB12/1000 -> 146506.69 | K16: =G16/$C16 -> 0.54476515 | L16: =H16/$C16 -> 0.57793564 | M16: =I16/$C16 -> 0.54476515 | N16: =J16/$C16 -> 0.57793564 | O16: =G16-$E16 -> -8408.7198 | P16: =H16-$E16 -> 0 | Q16: =I16-$E16 -> -8408.7198 | R16: =J16-$E16 -> 0 | S16: =$F16+O16 -> 0 | T16: =$F16+P16 -> 8408.7198 | U16: =$F16+Q16 -> 0 | V16: =$F16+R16 -> 8408.7198 | Y16: =Rep_Tri!A16 -> 2011 | Z16: =Rep_Tri!F16 -> 3307 | AA16: =Rep_Tri!F57 -> 1 | AB16: =AA16*Z16 -> 3307 | AD16: =Y16 -> 2011 | AE16: =Base_Indem_Sev!U16 -> 18448.583 | AF16: =Base_Indem_Sev!U57 -> 1 | AG16: =AE16*AF16 -> 18448.583 | AI16: =AD16 -> 2011 | AJ16: =Base_Med_Sev!U16 -> 22971.998 | AK16: =Base_Med_Sev!U57 -> 1 | AL16: =AJ16*AK16 -> 22971.998
B17: =Y13 -> 2008 | C17: =Summary!C16 -> 253500 | D17: =(AE13+AJ13)*Z13/1000 -> 137645.29 | E17: =(AE33+AJ33)*Z13/1000 -> 146315.96 | F17: =E17-D17 -> 8670.671 | G17: =Summary!G16 -> 137645.29 | H17: =Summary!H16 -> 146315.96 | I17: =(AG13+AL13)*AB13/1000 -> 137645.29 | J17: =(AG33+AL33)*AB13/1000 -> 146315.96 | K17: =G17/$C17 -> 0.54297945 | L17: =H17/$C17 -> 0.57718328 | M17: =I17/$C17 -> 0.54297945 | N17: =J17/$C17 -> 0.57718328 | O17: =G17-$E17 -> -8670.671 | P17: =H17-$E17 -> 0 | Q17: =I17-$E17 -> -8670.671 | R17: =J17-$E17 -> 0 | S17: =$F17+O17 -> 0 | T17: =$F17+P17 -> 8670.671 | U17: =$F17+Q17 -> 0 | V17: =$F17+R17 -> 8670.671 | Y17: =Rep_Tri!A17 -> 2012 | Z17: =Rep_Tri!E17 -> 3279 | AA17: =Rep_Tri!E57 -> 1 | AB17: =AA17*Z17 -> 3279 | AD17: =Y17 -> 2012 | AE17: =Base_Indem_Sev!T17 -> 18920.822 | AF17: =Base_Indem_Sev!T57 -> 1 | AG17: =AE17*AF17 -> 18920.822 | AI17: =AD17 -> 2012 | AJ17: =Base_Med_Sev!T17 -> 27142.003 | AK17: =Base_Med_Sev!T57 -> 1 | AL17: =AJ17*AK17 -> 27142.003
B18: =Y14 -> 2009 | C18: =Summary!C17 -> 267200 | D18: =(AE14+AJ14)*Z14/1000 -> 143627.13 | E18: =(AE34+AJ34)*Z14/1000 -> 154924.7 | F18: =E18-D18 -> 11297.563 | G18: =Summary!G17 -> 143627.13 | H18: =Summary!H17 -> 154924.7 | I18: =(AG14+AL14)*AB14/1000 -> 143627.13 | J18: =(AG34+AL34)*AB14/1000 -> 154924.7 | K18: =G18/$C18 -> 0.53752669 | L18: =H18/$C18 -> 0.57980799 | M18: =I18/$C18 -> 0.53752669 | N18: =J18/$C18 -> 0.57980799 | O18: =G18-$E18 -> -11297.563 | P18: =H18-$E18 -> 0 | Q18: =I18-$E18 -> -11297.563 | R18: =J18-$E18 -> 0 | S18: =$F18+O18 -> 0 | T18: =$F18+P18 -> 11297.563 | U18: =$F18+Q18 -> 0 | V18: =$F18+R18 -> 11297.563 | Y18: =Rep_Tri!A18 -> 2013 | Z18: =Rep_Tri!D18 -> 3085 | AA18: =Rep_Tri!D57 -> 1 | AB18: =AA18*Z18 -> 3085 | AD18: =Y18 -> 2013 | AE18: =Base_Indem_Sev!S18 -> 13341.977 | AF18: =Base_Indem_Sev!S57 -> 1 | AG18: =AE18*AF18 -> 13341.977 | AI18: =AD18 -> 2013 | AJ18: =Base_Med_Sev!S18 -> 22487.764 | AK18: =Base_Med_Sev!S57 -> 1 | AL18: =AJ18*AK18 -> 22487.764
B19: =Y15 -> 2010 | C19: =Summary!C18 -> 227700 | D19: =(AE15+AJ15)*Z15/1000 -> 136469.25 | E19: =(AE35+AJ35)*Z15/1000 -> 150887.79 | F19: =E19-D19 -> 14418.537 | G19: =Summary!G18 -> 136469.25 | H19: =Summary!H18 -> 150887.79 | I19: =(AG15+AL15)*AB15/1000 -> 136469.25 | J19: =(AG35+AL35)*AB15/1000 -> 150887.79 | K19: =G19/$C19 -> 0.59933794 | L19: =H19/$C19 -> 0.66266046 | M19: =I19/$C19 -> 0.59933794 | N19: =J19/$C19 -> 0.66266046 | O19: =G19-$E19 -> -14418.537 | P19: =H19-$E19 -> 0 | Q19: =I19-$E19 -> -14418.537 | R19: =J19-$E19 -> 0 | S19: =$F19+O19 -> 0 | T19: =$F19+P19 -> 14418.537 | U19: =$F19+Q19 -> 0 | V19: =$F19+R19 -> 14418.537 | Y19: =Rep_Tri!A19 -> 2014 | Z19: =Rep_Tri!C19 -> 2934 | AA19: =Rep_Tri!C57 -> 1 | AB19: =AA19*Z19 -> 2934 | AD19: =Y19 -> 2014 | AE19: =Base_Indem_Sev!R19 -> 9030.4152 | AF19: =Base_Indem_Sev!R57 -> 1 | AG19: =AE19*AF19 -> 9030.4152 | AI19: =AD19 -> 2014 | AJ19: =Base_Med_Sev!R19 -> 21951.605 | AK19: =Base_Med_Sev!R57 -> 1 | AL19: =AJ19*AK19 -> 21951.605
B20: =Y16 -> 2011 | C20: =Summary!C19 -> 225800 | D20: =(AE16+AJ16)*Z16/1000 -> 136977.86 | E20: =(AE36+AJ36)*Z16/1000 -> 157390.37 | F20: =E20-D20 -> 20412.504 | G20: =Summary!G19 -> 136977.86 | H20: =Summary!H19 -> 157390.37 | I20: =(AG16+AL16)*AB16/1000 -> 136977.86 | J20: =(AG36+AL36)*AB16/1000 -> 157390.37 | K20: =G20/$C20 -> 0.60663358 | L20: =H20/$C20 -> 0.69703439 | M20: =I20/$C20 -> 0.60663358 | N20: =J20/$C20 -> 0.69703439 | O20: =G20-$E20 -> -20412.504 | P20: =H20-$E20 -> 0 | Q20: =I20-$E20 -> -20412.504 | R20: =J20-$E20 -> 0 | S20: =$F20+O20 -> 0 | T20: =$F20+P20 -> 20412.504 | U20: =$F20+Q20 -> 0 | V20: =$F20+R20 -> 20412.504 | Y20: =Rep_Tri!A20 -> 2015 | Z20: =Rep_Tri!B20 -> 2538 | AA20: =Rep_Tri!B57 -> 1 | AB20: =AA20*Z20 -> 2538 | AD20: =Y20 -> 2015 | AE20: =Base_Indem_Sev!Q20 -> 3799.8378 | AF20: =Base_Indem_Sev!Q57 -> 1 | AG20: =AE20*AF20 -> 3799.8378 | AI20: =AD20 -> 2015 | AJ20: =Base_Med_Sev!Q20 -> 12953.748 | AK20: =Base_Med_Sev!Q57 -> 1 | AL20: =AJ20*AK20 -> 12953.748
B21: =Y17 -> 2012 | C21: =Summary!C20 -> 231900 | D21: =(AE17+AJ17)*Z17/1000 -> 151040 | E21: =(AE37+AJ37)*Z17/1000 -> 180451.43 | F21: =E21-D21 -> 29411.431 | G21: =Summary!G20 -> 151040 | H21: =Summary!H20 -> 180451.43 | I21: =(AG17+AL17)*AB17/1000 -> 151040 | J21: =(AG37+AL37)*AB17/1000 -> 180451.43 | K21: =G21/$C21 -> 0.65131523 | L21: =H21/$C21 -> 0.7781433 | M21: =I21/$C21 -> 0.65131523 | N21: =J21/$C21 -> 0.7781433 | O21: =G21-$E21 -> -29411.431 | P21: =H21-$E21 -> 0 | Q21: =I21-$E21 -> -29411.431 | R21: =J21-$E21 -> 0 | S21: =$F21+O21 -> 0 | T21: =$F21+P21 -> 29411.431 | U21: =$F21+Q21 -> 0 | V21: =$F21+R21 -> 29411.431
